Workbook

Sheet 카탈로그
A1: 코드 | B1: 품목명 | C1: 구역 | D1: 등록방식 | E1: 기준 | F1: 주기(일) | G1: 주기(사용량) | H1: 단위 | I1: 계절 | J1: 안전잠금 | K1: 온보딩추천 | L1: 근거·비고
A2: bath_toothbrush | B2: 칫솔 | C2: 욕실 | D2: 목록선택 | E2: 날짜 | F2: 90 | I2: 연중 | K2: ○ | L2: 칫솔모가 벌어지면 플라그 제거력 저하. 마모 시 조기 교체
A3: bath_ebrush_head | B3: 전동칫솔 브러시헤드 | C3: 욕실 | D3: 목록선택 | E3: 날짜 | F3: 90 | I3: 연중 | L3: 수동 칫솔과 동일 기준
A4: bath_interdental | B4: 치간칫솔 | C4: 욕실 | D4: 목록선택 | E4: 날짜 | F4: 7 | I4: 연중 | L4: 모가 휘면 즉시 교체
A5: bath_tongue | B5: 혀클리너 | C5: 욕실 | D5: 목록선택 | E5: 날짜 | F5: 90 | I5: 연중
A6: bath_razor | B6: 면도날 | C6: 욕실 | D6: 목록선택 | E6: 날짜 | F6: 21 | I6: 연중 | K6: ○ | L6: 사용 5~10회 기준, 매일 면도 시 약 2~3주
A7: bath_showertowel | B7: 샤워타월(때수건) | C7: 욕실 | D7: 목록선택 | E7: 날짜 | F7: 60 | I7: 연중 | K7: ○ | L7: 습한 환경에서 세균 번식. 2개월 권장
A8: bath_towel | B8: 수건 | C8: 욕실 | D8: 목록선택 | E8: 날짜 | F8: 730 | I8: 연중 | L8: 2년. 뻣뻣해지면 조기 교체
A9: bath_bathmat_wash | B9: 욕실 발매트 세탁 | C9: 욕실 | D9: 목록선택 | E9: 날짜 | F9: 14 | I9: 연중
A10: bath_slipper | B10: 욕실 슬리퍼 | C10: 욕실 | D10: 목록선택 | E10: 날짜 | F10: 180 | I10: 연중
A11: bath_drain_net | B11: 배수구 거름망 | C11: 욕실 | D11: 목록선택 | E11: 날짜 | F11: 30 | I11: 연중
A12: bath_toiletbrush | B12: 변기솔 | C12: 욕실 | D12: 목록선택 | E12: 날짜 | F12: 180 | I12: 연중
A13: bath_curtain_wash | B13: 샤워커튼 세탁 | C13: 욕실 | D13: 목록선택 | E13: 날짜 | F13: 30 | I13: 연중 | L13: 곰팡이 발생 전 주기적 세탁
A14: bath_soapnet | B14: 비누 거품망 | C14: 욕실 | D14: 목록선택 | E14: 날짜 | F14: 30 | I14: 연중
A15: bath_cup_clean | B15: 양치컵·칫솔꽂이 세척 | C15: 욕실 | D15: 목록선택 | E15: 날짜 | F15: 14 | I15: 연중 | L15: 바닥 물때가 세균 온상
A16: bath_toothpaste | B16: 치약 (개봉 후) | C16: 욕실 | D16: 개봉일 | E16: 날짜 | F16: 365 | I16: 연중 | L16: 개봉 후 1년
A17: bath_mouthwash | B17: 구강청결제 (개봉 후) | C17: 욕실 | D17: 개봉일 | E17: 날짜 | F17: 180 | I17: 연중
A18: bath_hairbrush_clean | B18: 헤어브러시 세척 | C18: 욕실 | D18: 목록선택 | E18: 날짜 | F18: 30 | I18: 연중
A19: bath_hairbrush | B19: 헤어브러시 교체 | C19: 욕실 | D19: 목록선택 | E19: 날짜 | F19: 365 | I19: 연중
A20: bath_mold_clean | B20: 욕실 곰팡이 청소 | C20: 욕실 | D20: 목록선택 | E20: 날짜 | F20: 90 | I20: 연중
A21: bath_showerhead_clean | B21: 샤워기 헤드 세척 | C21: 욕실 | D21: 목록선택 | E21: 날짜 | F21: 90 | I21: 연중 | L21: 구연산 세척. 부품 교체 아님
A22: bath_sponge | B22: 목욕 스펀지 | C22: 욕실 | D22: 목록선택 | E22: 날짜 | F22: 60 | I22: 연중
A23: bath_nailclipper | B23: 손톱깎이 소독 | C23: 욕실 | D23: 목록선택 | E23: 날짜 | F23: 90 | I23: 연중
A24: kit_sponge | B24: 수세미 | C24: 주방 | D24: 목록선택 | E24: 날짜 | F24: 30 | I24: 연중 | K24: ○ | L24: 젖은 수세미는 세균 다수. 1개월 권장
A25: kit_dishcloth | B25: 행주 | C25: 주방 | D25: 목록선택 | E25: 날짜 | F25: 30 | I25: 연중 | K25: ○ | L25: 삶거나 교체
A26: kit_gloves | B26: 고무장갑 | C26: 주방 | D26: 목록선택 | E26: 날짜 | F26: 30 | I26: 연중 | K26: ○ | L26: 1개월 권장
A27: kit_board_plastic | B27: 도마 (플라스틱) | C27: 주방 | D27: 목록선택 | E27: 날짜 | F27: 365 | I27: 연중 | L27: 칼자국 홈에 세균. 1년 권장
A28: kit_board_wood | B28: 도마 (나무) | C28: 주방 | D28: 목록선택 | E28: 날짜 | F28: 365 | I28: 연중
A29: kit_pan_coated | B29: 프라이팬 (코팅) | C29: 주방 | D29: 목록선택 | E29: 날짜 | F29: 730 | I29: 연중 | L29: 코팅 벗겨지면 즉시 교체
A30: kit_knife_sharpen | B30: 칼 연마 | C30: 주방 | D30: 목록선택 | E30: 날짜 | F30: 90 | I30: 연중
A31: kit_wood_utensil | B31: 나무 수저·주걱 | C31: 주방 | D31: 목록선택 | E31: 날짜 | F31: 180 | I31: 연중
A32: kit_silicone | B32: 실리콘 조리도구 | C32: 주방 | D32: 목록선택 | E32: 날짜 | F32: 365 | I32: 연중
A33: kit_container | B33: 플라스틱 밀폐용기 | C33: 주방 | D33: 목록선택 | E33: 날짜 | F33: 90 | I33: 연중 | L33: 흠집·변색 시 교체. 3개월 이상 권장하지 않음
A34: kit_container_seal | B34: 밀폐용기 패킹 | C34: 주방 | D34: 목록선택 | E34: 날짜 | F34: 180 | I34: 연중
A35: kit_tumbler_seal | B35: 텀블러 패킹 | C35: 주방 | D35: 목록선택 | E35: 날짜 | F35: 180 | I35: 연중 | L35: 패킹 틈이 곰팡이 발생 지점
A36: kit_sink_net | B36: 싱크대 배수구망 | C36: 주방 | D36: 목록선택 | E36: 날짜 | F36: 30 | I36: 연중
A37: kit_foodbin_clean | B37: 음식물 쓰레기통 세척 | C37: 주방 | D37: 목록선택 | E37: 날짜 | F37: 7 | I37: 연중
A38: kit_fridge_deo | B38: 냉장고 탈취제 | C38: 주방 | D38: 목록선택 | E38: 날짜 | F38: 90 | I38: 연중
A39: kit_fridge_clean | B39: 냉장고 청소 | C39: 주방 | D39: 목록선택 | E39: 날짜 | F39: 90 | I39: 연중
A40: kit_kettle_clean | B40: 전기포트 세척 | C40: 주방 | D40: 목록선택 | E40: 날짜 | F40: 90 | I40: 연중 | L40: 구연산 세척
...

Sheet 요약
A1: 제때 프리셋 카탈로그 — 요약
A2: 필터류·차량 제외 버전 (v0.1)
A4: 구역 | B4: 품목 수 | C4: 개봉일 기준 | D4: 안전잠금
A5: 욕실 | B5: =COUNTIF(카탈로그!$C$2:$C$160,A5) -> 22 | C5: =COUNTIFS(카탈로그!$C$2:$C$160,A5,카탈로그!$D$2:$D$160,"개봉일") -> 2 | D5: =COUNTIFS(카탈로그!$C$2:$C$160,A5,카탈로그!$J$2:$J$160,"○") -> 0
A6: 주방 | B6: =COUNTIF(카탈로그!$C$2:$C$160,A6) -> 30 | C6: =COUNTIFS(카탈로그!$C$2:$C$160,A6,카탈로그!$D$2:$D$160,"개봉일") -> 6 | D6: =COUNTIFS(카탈로그!$C$2:$C$160,A6,카탈로그!$J$2:$J$160,"○") -> 0
A7: 침실 | B7: =COUNTIF(카탈로그!$C$2:$C$160,A7) -> 16 | C7: =COUNTIFS(카탈로그!$C$2:$C$160,A7,카탈로그!$D$2:$D$160,"개봉일") -> 0 | D7: =COUNTIFS(카탈로그!$C$2:$C$160,A7,카탈로그!$J$2:$J$160,"○") -> 0
A8: 거실 | B8: =COUNTIF(카탈로그!$C$2:$C$160,A8) -> 23 | C8: =COUNTIFS(카탈로그!$C$2:$C$160,A8,카탈로그!$D$2:$D$160,"개봉일") -> 0 | D8: =COUNTIFS(카탈로그!$C$2:$C$160,A8,카탈로그!$J$2:$J$160,"○") -> 0
A9: 미용 | B9: =COUNTIF(카탈로그!$C$2:$C$160,A9) -> 30 | C9: =COUNTIFS(카탈로그!$C$2:$C$160,A9,카탈로그!$D$2:$D$160,"개봉일") -> 21 | D9: =COUNTIFS(카탈로그!$C$2:$C$160,A9,카탈로그!$J$2:$J$160,"○") -> 0
A10: 건강 | B10: =COUNTIF(카탈로그!$C$2:$C$160,A10) -> 10 | C10: =COUNTIFS(카탈로그!$C$2:$C$160,A10,카탈로그!$D$2:$D$160,"개봉일") -> 3 | D10: =COUNTIFS(카탈로그!$C$2:$C$160,A10,카탈로그!$J$2:$J$160,"○") -> 3
A11: 안전 | B11: =COUNTIF(카탈로그!$C$2:$C$160,A11) -> 8 | C11: =COUNTIFS(카탈로그!$C$2:$C$160,A11,카탈로그!$D$2:$D$160,"개봉일") -> 0 | D11: =COUNTIFS(카탈로그!$C$2:$C$160,A11,카탈로그!$J$2:$J$160,"○") -> 8
A12: 세탁 | B12: =COUNTIF(카탈로그!$C$2:$C$160,A12) -> 12 | C12: =COUNTIFS(카탈로그!$C$2:$C$160,A12,카탈로그!$D$2:$D$160,"개봉일") -> 0 | D12: =COUNTIFS(카탈로그!$C$2:$C$160,A12,카탈로그!$J$2:$J$160,"○") -> 0
A13: 전자 | B13: =COUNTIF(카탈로그!$C$2:$C$160,A13) -> 8 | C13: =COUNTIFS(카탈로그!$C$2:$C$160,A13,카탈로그!$D$2:$D$160,"개봉일") -> 0 | D13: =COUNTIFS(카탈로그!$C$2:$C$160,A13,카탈로그!$J$2:$J$160,"○") -> 0
A14: 합계 | B14: =SUM(B5:B13) -> 159 | C14: =SUM(C5:C13) -> 32 | D14: =SUM(D5:D13) -> 11
A16: 주기 분포
A17: 1주 이하 | B17: =COUNTIFS(카탈로그!$F$2:$F$160,">="&0,카탈로그!$F$2:$F$160,"<="&7) -> 9
A18: 1개월 이하 | B18: =COUNTIFS(카탈로그!$F$2:$F$160,">="&8,카탈로그!$F$2:$F$160,"<="&31) -> 34
A19: 3개월 이하 | B19: =COUNTIFS(카탈로그!$F$2:$F$160,">="&32,카탈로그!$F$2:$F$160,"<="&92) -> 37
A20: 1년 이하 | B20: =COUNTIFS(카탈로그!$F$2:$F$160,">="&93,카탈로그!$F$2:$F$160,"<="&365) -> 61
A21: 1년 초과 | B21: =COUNTIFS(카탈로그!$F$2:$F$160,">="&366,카탈로그!$F$2:$F$160,"<="&99999) -> 18

Sheet 범례
A1: 읽는 법 · 고치는 법
A3: 등록방식
A4: 목록선택 | B4: 목록에서 탭 한 번으로 등록. 오늘이 기준일이 된다
A5: 개봉일 | B5: 개봉한 날이 기준일. 앱에서 '오늘 개봉' 또는 날짜 선택
A7: 기준
A8: 날짜 | B8: 달력으로 센다. 대부분의 품목
A9: 사용량 | B9: 주행거리·착용 횟수로 센다. Phase 4 기능
A11: 계절
A12: 연중 | B12: 항상 카운트
A13: 여름 / 겨울 | B13: 시즌 밖에는 카운트를 멈춘다. 시즌 시작 시 '쓰기 시작하셨어요?' 1회 확인
A15: 안전잠금 | B15: ○ 표시 품목은 주기 자기교정 대상에서 제외한다.
B16: 사용자가 늦게 바꾸더라도 권장 주기를 그대로 유지한다. (붉은 배경 행)
A18: 온보딩추천 | B18: ○ 표시 품목은 온보딩에서 기본 체크로 제시한다.
B19: 짧은 주기 품목을 반드시 포함시켜 2주 안에 첫 알림이 도착하게 한다.
A21: 고칠 때 | B21: 주기(일) 열만 고치면 된다. 나머지 열은 앱 동작을 바꾸므로 신중히.
B22: 새 품목을 추가할 때는 코드를 '구역약어_영문명' 형식으로 중복 없이 붙인다.
A24: 주의 | B24: 여기 적힌 주기는 일반적인 권장값이다. 제조사 권장값이 있으면 그것이 우선한다.
B25: 안전 품목(화재감지기·소화기·가스)은 임의로 늘리지 말 것.
